Workbook

Sheet Sheet1
A1: Dấu thời gian | B1: Your name | C1: Your class | D1: Your first name's teammate | E1: 1. Attend group meetings | F1: 2. Contribute | G1: 3. Complete the work assigned by the group | H1: 4. Cooperation with team members | I1: 5. Improve working methods to improve efficiency and quality | J1: 6. Have creative ideas | K1: 7. Quality of work assigned by the team | L1: Your second name's teammate | M1: 1. Attend group meetings | N1: 2. Contribute | O1: 3. Complete the work assigned by the group | P1: 4. Cooperation with team members | Q1: 5. Improve working methods to improve efficiency and quality | R1: 6. Have creative ideas | S1: 7. Quality of work assigned by the team | T1: Your third name's teammate | U1: 1. Attend group meetings | V1: 2. Contribute | W1: 3. Complete the work assigned by the group | X1: 4. Cooperation with team members | Y1: 5. Improve working methods to improve efficiency and quality | Z1: 6. Have creative ideas | AA1: 7. Quality of work assigned by the team | AB1: Địa chỉ email
A5: 44536.084 | B5: Nguyễn Đức Khải | C5: CS4273.M11 | D5: Cao Hoàng Khang | E5: Regularly: 10 | F5: Sometimes: 5 | G5: Regularly: 15 | H5: Good: 10 | I5: Never: 0 | J5: Never: 0 | K5: Medium: 10 | L5: Trần Quang Minh | M5: Full: 15 | N5: Sometimes: 5 | O5: Regularly: 15 | P5: Bad: 0 | Q5: Never: 0 | R5: Regulary: 10 | S5: Bad: 0 | T5: Nguyễn Đức Khải(Leader) | U5: Full: 15 | V5: Positive: 15 | W5: Always: 20 | X5: Good: 10 | Y5: Regularly: 10 | Z5: Regulary: 10 | AA5: Good: 15 | AB5: 19521658@gm.uit.edu.vn
A6: 44902.551 | B6: Võ Thành Tú | C6: CS4273.N12.1 | AB6: 20522105@gm.uit.edu.vn
A7: 44903.328 | B7: Trần Trọng Sang | C7: CS4273.N12.1 | D7: Lê Minh Thông | E7: Full: 15 | F7: Positive: 15 | G7: Always: 20 | H7: Good: 10 | I7: Regularly: 10 | J7: Always: 15 | K7: Good: 15 | L7: Phạm Thùy Dung | M7: Full: 15 | N7: Positive: 15 | O7: Always: 20 | P7: Good: 10 | Q7: Regularly: 10 | R7: Always: 15 | S7: Good: 15 | T7: Võ Anh Hào | U7: Full: 15 | V7: Positive: 15 | W7: Always: 20 | X7: Good: 10 | Y7: Regularly: 10 | Z7: Always: 15 | AA7: Good: 15 | AB7: 20521834@gm.uit.edu.vn
A8: 44903.386 | B8: Đậu Đình Quang Anh | C8: CS4273.N12.1 | D8: Trần Đức Duy | E8: Full: 15 | F8: Positive: 15 | G8: Always: 20 | H8: Good: 10 | I8: Regularly: 10 | J8: Always: 15 | K8: Good: 15 | L8: Hà Gia Huy | M8: Full: 15 | N8: Positive: 15 | O8: Always: 20 | P8: Good: 10 | Q8: Regularly: 10 | R8: Always: 15 | S8: Good: 15 | T8: Nguyễn Đình Đan Thy | U8: Full: 15 | V8: Positive: 15 | W8: Always: 20 | X8: Good: 10 | Y8: Regularly: 10 | Z8: Always: 15 | AA8: Good: 15 | AB8: 20521059@gm.uit.edu.vn
A9: 44903.386 | B9: Võ Anh Hào | C9: CS4273.N12.1 | D9: Lê Minh Thông | E9: Full: 15 | F9: Positive: 15 | G9: Always: 20 | H9: Good: 10 | I9: Regularly: 10 | J9: Always: 15 | K9: Good: 15 | L9: Phạm Thùy Dung | M9: Full: 15 | N9: Positive: 15 | O9: Always: 20 | P9: Good: 10 | Q9: Regularly: 10 | R9: Always: 15 | S9: Good: 15 | T9: Trần Trọng Sang | U9: Full: 15 | V9: Positive: 15 | W9: Always: 20 | X9: Good: 10 | Y9: Regularly: 10 | Z9: Always: 15 | AA9: Good: 15 | AB9: 20521297@gm.uit.edu.vn
A10: 44903.387 | B10: Trần Đức Duy | C10: CS4273.N12.1 | D10: Đậu Đình Quang Anh | E10: Full: 15 | F10: Positive: 15 | G10: Always: 20 | H10: Good: 10 | I10: Regularly: 10 | J10: Always: 15 | K10: Good: 15 | L10: Hà Gia Huy | M10: Full: 15 | N10: Positive: 15 | O10: Always: 20 | P10: Good: 10 | Q10: Regularly: 10 | R10: Always: 15 | S10: Good: 15 | T10: Nguyễn Đình Đan Thy | U10: Full: 15 | V10: Positive: 15 | W10: Always: 20 | X10: Good: 10 | Y10: Regularly: 10 | Z10: Always: 15 | AA10: Good: 15 | AB10: 20521248@gm.uit.edu.vn
A11: 44903.387 | B11: Huan Vo Trong | C11: CS4273.N12.1 | D11: Bùi Quang Giàu | E11: Full: 15 | F11: Regularly: 10 | G11: Always: 20 | H11: Good: 10 | I11: Often: 5 | J11: Always: 15 | K11: Good: 15 | L11: Nguyễn Bảo Lâm | M11: Full: 15 | N11: Regularly: 10 | O11: Always: 20 | P11: Good: 10 | Q11: Regularly: 10 | R11: Regulary: 10 | S11: Good: 15 | T11: Đỗ Công Trình | U11: Full: 15 | V11: Positive: 15 | W11: Always: 20 | X11: Good: 10 | Y11: Regularly: 10 | Z11: Always: 15 | AA11: Good: 15 | AB11: 20520524@gm.uit.edu.vn
A12: 44903.388 | B12: Nguyễn Đình Đan Thy | C12: CS4273.N12.1 | D12: Đậu Đình Quang Anh | E12: Full: 15 | F12: Positive: 15 | G12: Always: 20 | H12: Good: 10 | I12: Regularly: 10 | J12: Always: 15 | K12: Good: 15 | L12: Trần Đức Duy | M12: Full: 15 | N12: Positive: 15 | O12: Always: 20 | P12: Good: 10 | Q12: Regularly: 10 | R12: Always: 15 | S12: Good: 15 | T12: Hà Gia Huy | U12: Full: 15 | V12: Positive: 15 | W12: Always: 20 | X12: Good: 10 | Y12: Regularly: 10 | Z12: Always: 15 | AA12: Good: 15 | AB12: 20522006@gm.uit.edu.vn
A13: 44903.39 | B13: Hà Gia Huy | C13: CS4273.N12.1 | D13: Đậu Đình Quang Anh | E13: Full: 15 | F13: Positive: 15 | G13: Always: 20 | H13: Good: 10 | I13: Regularly: 10 | J13: Always: 15 | K13: Good: 15 | L13: Trần Đức Duy | M13: Full: 15 | N13: Positive: 15 | O13: Always: 20 | P13: Good: 10 | Q13: Regularly: 10 | R13: Always: 15 | S13: Good: 15 | T13: Nguyễn Đình Đan Thy | U13: Full: 15 | V13: Positive: 15 | W13: Always: 20 | X13: Good: 10 | Y13: Regularly: 10 | Z13: Always: 15 | AA13: Good: 15 | AB13: 20521385@gm.uit.edu.vn
A14: 44903.39 | B14: Đỗ Công Trình | C14: CS4273.N12.1 | D14: Võ Trọng Huân | E14: Full: 15 | F14: Positive: 15 | G14: Always: 20 | H14: Good: 10 | I14: Regularly: 10 | J14: Always: 15 | K14: Good: 15 | L14: Bùi Quang Giàu | M14: Full: 15 | N14: Positive: 15 | O14: Always: 20 | P14: Normal: 5 | Q14: Regularly: 10 | R14: Always: 15 | S14: Good: 15 | T14: Nguyễn Bảo Lâm | U14: Full: 15 | V14: Positive: 15 | W14: Always: 20 | X14: Normal: 5 | Y14: Regularly: 10 | Z14: Always: 15 | AA14: Good: 15 | AB14: 20522058@gm.uit.edu.vn
A15: 44903.517 | B15: Nguyễn Bảo Lâm | C15: CS4273.N12.1 | D15: Đỗ Công Trình | E15: Full: 15 | F15: Positive: 15 | G15: Always: 20 | H15: Good: 10 | I15: Regularly: 10 | J15: Always: 15 | K15: Good: 15 | L15: Bùi Quang Giàu | M15: Full: 15 | N15: Positive: 15 | O15: Always: 20 | P15: Good: 10 | Q15: Regularly: 10 | R15: Always: 15 | S15: Good: 15 | T15: Võ Trọng Huân | U15: Full: 15 | V15: Positive: 15 | W15: Always: 20 | X15: Good: 10 | Y15: Often: 5 | Z15: Regulary: 10 | AA15: Medium: 10 | AB15: 20521515@gm.uit.edu.vn
A16: 44903.522 | B16: Lê Minh Thông | C16: CS4273.N12.1 | D16: Phạm Thị Dung | E16: Full: 15 | F16: Positive: 15 | G16: Always: 20 | H16: Good: 10 | I16: Regularly: 10 | J16: Always: 15 | K16: Good: 15 | L16: Trần Trọng Sang | M16: Regularly: 10 | N16: Positive: 15 | O16: Regularly: 15 | P16: Good: 10 | Q16: Regularly: 10 | R16: Regulary: 10 | S16: Good: 15 | T16: Võ Anh Hào | U16: Often: 5 | V16: Regularly: 10 | W16: Regularly: 15 | X16: Normal: 5 | Y16: Often: 5 | Z16: Regulary: 10 | AA16: Medium: 10 | AB16: 20521981@gm.uit.edu.vn
A17: 44903.551 | B17: Trần Trọng Sang | C17: CS4273.N12.1 | D17: Trần Trọng Sang | E17: Regularly: 10 | F17: Positive: 15 | G17: Regularly: 15 | H17: Good: 10 | I17: Regularly: 10 | J17: Sometines: 5 | K17: Medium: 10 | L17: Phạm Thùy Dung | M17: Full: 15 | N17: Regularly: 10 | O17: Regularly: 15 | P17: Good: 10 | Q17: Regularly: 10 | R17: Always: 15 | S17: Good: 15 | T17: Lê Minh Thông | U17: Full: 15 | V17: Positive: 15 | W17: Always: 20 | X17: Good: 10 | Y17: Regularly: 10 | Z17: Always: 15 | AA17: Good: 15 | AB17: 20521834@gm.uit.edu.vn
A18: 44903.575 | B18: Đồng Phúc Nhẫn | C18: CS4273.N12.1 | D18: Nghĩa | E18: Full: 15 | F18: Positive: 15 | G18: Always: 20 | H18: Good: 10 | I18: Regularly: 10 | J18: Always: 15 | K18: Good: 15 | L18: Bình | M18: Full: 15 | N18: Positive: 15 | O18: Always: 20 | P18: Good: 10 | Q18: Regularly: 10 | R18: Always: 15 | S18: Good: 15 | T18: Tỷ | U18: Full: 15 | V18: Positive: 15 | W18: Always: 20 | X18: Good: 10 | Y18: Regularly: 10 | Z18: Always: 15 | AA18: Good: 15 | AB18: 20521694@gm.uit.edu.vn
... A20: 44903.595 | B20: Ngô Bá Trọng Nghĩa | C20: CS4273.N12.1 | D20: Đồng Phúc Nhẫn | E20: Full: 15 | F20: Positive: 15 | G20: Always: 20 | H20: Good: 10 | I20: Regularly: 10 | J20: Always: 15 | K20: Good: 15 | L20: Nguyễn Thanh Bình | M20: Full: 15 | N20: Positive: 15 | O20: Always: 20 | P20: Good: 10 | Q20: Regularly: 10 | R20: Always: 15 | S20: Good: 15 | T20: Phạm Phước Tỷ | U20: Full: 15 | V20: Positive: 15 | W20: Always: 20 | X20: Good: 10 | Y20: Regularly: 10 | Z20: Always: 15 | AA20: Good: 15 | AB20: 20521653@gm.uit.edu.vn
A21: 44903.613 | B21: Lê Trí Khoa | C21: CS4273.N12.1 | D21: Lâm Lê Phúc Huy | E21: Full: 15 | F21: Positive: 15 | G21: Always: 20 | H21: Good: 10 | I21: Often: 5 | J21: Regulary: 10 | K21: Good: 15 | L21: Nguyễn Hữu Thiên | M21: Full: 15 | N21: Positive: 15 | O21: Always: 20 | P21: Good: 10 | Q21: Never: 0 | R21: Sometines: 5 | S21: Good: 15 | T21: Nguyễn Phi Hùng | V21: Positive: 15 | W21: Always: 20 | X21: Good: 10 | Y21: Regularly: 10 | Z21: Regulary: 10 | AA21: Good: 15 | AB21: 20521466@gm.uit.edu.vn
A22: 44903.615 | B22: Nguyễn Phi Hùng | C22: CS4273.N12.1 | D22: Khoa | E22: Full: 15 | F22: Positive: 15 | G22: Always: 20 | H22: Good: 10 | I22: Regularly: 10 | J22: Always: 15 | K22: Good: 15 | L22: Huy | M22: Full: 15 | N22: Positive: 15 | O22: Always: 20 | P22: Good: 10 | Q22: Regularly: 10 | R22: Always: 15 | S22: Good: 15 | T22: Thiên | U22: Full: 15 | V22: Positive: 15 | W22: Always: 20 | X22: Good: 10 | Y22: Regularly: 10 | Z22: Always: 15 | AA22: Good: 15 | AB22: 20521425@gm.uit.edu.vn
A23: 44903.625 | B23: Nguyễn Hữu Thiên | C23: CS4273.N12.1 | D23: Lê Trí Khoa | E23: Full: 15 | F23: Positive: 15 | G23: Always: 20 | H23: Good: 10 | I23: Regularly: 10 | J23: Always: 15 | K23: Good: 15 | L23: Lâm Lê Phúc Huy | M23: Full: 15 | N23: Positive: 15 | O23: Always: 20 | P23: Good: 10 | Q23: Regularly: 10 | R23: Regulary: 10 | S23: Good: 15 | T23: Nguyễn Phi Hùng | U23: Full: 15 | V23: Positive: 15 | W23: Always: 20 | X23: Good: 10 | Y23: Often: 5 | Z23: Regulary: 10 | AA23: Good: 15 | AB23: 20521951@gm.uit.edu.vn
A24: 44903.758 | B24: Phạm Thùy Dung | C24: CS4273.N12.1 | D24: Trần Trọng Sang | E24: Often: 5 | F24: Sometimes: 5 | G24: Sometimes: 10 | H24: Normal: 5 | I24: Often: 5 | J24: Sometines: 5 | K24: Medium: 10 | L24: Võ Anh Hào | M24: Often: 5 | N24: Sometimes: 5 | O24: Sometimes: 10 | P24: Normal: 5 | Q24: Often: 5 | R24: Sometines: 5 | S24: Medium: 10 | T24: Lê Minh Thông | U24: Regularly: 10 | V24: Regularly: 10 | W24: Regularly: 15 | X24: Good: 10 | Y24: Often: 5 | Z24: Sometines: 5 | AA24: Medium: 10 | AB24: 20521214@gmail.com
A25: 44904.681 | B25: Lâm Lê Phúc Huy | C25: CS4273.N12.1 | D25: Lê Trí Khoa | E25: Full: 15 | F25: Positive: 15 | G25: Always: 20 | H25: Good: 10 | I25: Regularly: 10 | J25: Always: 15 | K25: Good: 15 | L25: Nguyễn Hữu Thiên | M25: Full: 15 | N25: Positive: 15 | O25: Always: 20 | P25: Good: 10 | Q25: Regularly: 10 | R25: Regulary: 10 | S25: Good: 15 | T25: Nguyễn Phi Hùng | U25: Full: 15 | V25: Positive: 15 | W25: Always: 20 | X25: Good: 10 | Y25: Regularly: 10 | Z25: Always: 15 | AA25: Good: 15 | AB25: 20521388@gm.uit.edu.vn
A26: 44916.85 | B26: Dương Minh Thành | C26: CS4273.N11.1 | AB26: 17521044@gm.uit.edu.vn
A27: 44917.563 | B27: Nguyễn Nhất Thưởng | C27: CS4273.N11.1 | D27: Phạm Thành Đạt | E27: Full: 15 | F27: Positive: 15 | G27: Always: 20 | H27: Good: 10 | I27: Regularly: 10 | J27: Always: 15 | K27: Good: 15 | L27: Nguyễn Quang Vy | M27: Full: 15 | N27: Positive: 15 | O27: Always: 20 | P27: Good: 10 | Q27: Regularly: 10 | R27: Always: 15 | S27: Good: 15 | T27: Thiều Huy Hoàng | U27: Full: 15 | V27: Positive: 15 | W27: Always: 20 | X27: Good: 10 | Y27: Regularly: 10 | Z27: Always: 15 | AA27: Good: 15 | AB27: 20522000@gm.uit.edu.vn
A28: 44917.565 | B28: Thiều Huy Hoàng | C28: CS4273.N11.1 | D28: Phạm Thành Đạt | E28: Full: 15 | F28: Positive: 15 | G28: Always: 20 | H28: Good: 10 | I28: Regularly: 10 | J28: Always: 15 | K28: Good: 15 | L28: Nguyễn Quang Vy | M28: Full: 15 | N28: Positive: 15 | O28: Always: 20 | P28: Good: 10 | Q28: Regularly: 10 | R28: Always: 15 | S28: Good: 15 | T28: Nguyễn Nhất Thưởng | U28: Full: 15 | V28: Positive: 15 | W28: Always: 20 | X28: Good: 10 | Y28: Regularly: 10 | Z28: Always: 15 | AA28: Good: 15 | AB28: 20521350@gm.uit.edu.vn
A29: 44917.569 | B29: Phạm Thành Đạt | C29: CS4273.N11.1 | D29: Thiều Huy Hoàng | E29: Full: 15 | F29: Positive: 15 | G29: Always: 20 | H29: Good: 10 | I29: Regularly: 10 | J29: Always: 15 | K29: Good: 15 | L29: Nguyễn Quang Vy | M29: Full: 15 | N29: Positive: 15 | O29: Always: 20 | P29: Good: 10 | Q29: Regularly: 10 | R29: Always: 15 | S29: Good: 15 | T29: Nguyễn Nhất Thưởng | U29: Full: 15 | V29: Positive: 15 | W29: Always: 20 | X29: Good: 10 | Y29: Regularly: 10 | Z29: Always: 15 | AA29: Good: 15 | AB29: 20521175@gm.uit.edu.vn
A30: 44917.57 | B30: Nguyễn Quang Vy | C30: CS4273.N11.1 | D30: Phạm Thành Đạt | E30: Full: 15 | F30: Positive: 15 | G30: Always: 20 | H30: Good: 10 | I30: Regularly: 10 | J30: Always: 15 | K30: Good: 15 | L30: Thiều Huy Hoàng | M30: Full: 15 | N30: Positive: 15 | O30: Always: 20 | P30: Good: 10 | Q30: Regularly: 10 | R30: Always: 15 | S30: Good: 15 | T30: Nguyễn Nhất Thưởng | U30: Full: 15 | V30: Positive: 15 | W30: Always: 20 | X30: Good: 10 | Y30: Regularly: 10 | Z30: Always: 15 | AA30: Good: 15 | AB30: 20522181@gm.uit.edu.vn
A31: 44917.585 | B31: Lê Quang Hòa | C31: CS4273.N11.1 | D31: Kiều Xuân Diệu Hương | E31: Full: 15 | F31: Positive: 15 | G31: Always: 20 | H31: Good: 10 | I31: Regularly: 10 | J31: Always: 15 | K31: Good: 15 | L31: Bùi Thu Hà | M31: Full: 15 | N31: Positive: 15 | O31: Always: 20 | P31: Good: 10 | Q31: Regularly: 10 | R31: Always: 15 | S31: Good: 15 | T31: Phạm Thị Thùy Dương | U31: Full: 15 | V31: Positive: 15 | W31: Always: 20 | X31: Good: 10 | Y31: Regularly: 10 | Z31: Always: 15 | AA31: Good: 15 | AB31: 20521331@gm.uit.edu.vn
A32: 44917.597 | B32: Nguyễn Thị Ngọc Thảo | C32: CS4273.N11.1 | D32: Nguyễn Ngọc Huyền | E32: Full: 15 | F32: Positive: 15 | G32: Always: 20 | H32: Good: 10 | I32: Regularly: 10 | J32: Always: 15 | K32: Good: 15 | L32: Phạm Hà Minh Quyên | M32: Full: 15 | N32: Positive: 15 | O32: Always: 20 | P32: Good: 10 | Q32: Regularly: 10 | R32: Always: 15 | S32: Good: 15 | T32: Nguyễn Trần Chí Đức | U32: Full: 15 | V32: Positive: 15 | W32: Always: 20 | X32: Good: 10 | Z32: Always: 15 | AA32: Good: 15 | AB32: 20521935@gm.uit.edu.vn
A33: 44917.6 | B33: Phạm Hà Minh Quyên | C33: CS4273.N11.1 | D33: Nguyễn Ngọc Huyền | E33: Full: 15 | F33: Positive: 15 | G33: Always: 20 | H33: Good: 10 | I33: Regularly: 10 | J33: Always: 15 | K33: Good: 15 | L33: Nguyễn Thị Ngọc Thảo | M33: Full: 15 | N33: Positive: 15 | O33: Always: 20 | P33: Good: 10 | Q33: Regularly: 10 | R33: Always: 15 | S33: Good: 15 | T33: Nguyễn Trần Chí Đức | U33: Full: 15 | V33: Positive: 15 | W33: Always: 20 | X33: Good: 10 | Y33: Regularly: 10 | Z33: Always: 15 | AA33: Good: 15 | AB33: 20521824@gm.uit.edu.vn
A34: 44917.602 | B34: Nguyễn Minh Thành | C34: CS4273.N11.1 | D34: Nguyễn Minh Thành | E34: Full: 15 | F34: Positive: 15 | G34: Regularly: 15 | H34: Good: 10 | I34: Regularly: 10 | J34: Regulary: 10 | K34: Good: 15 | L34: Nguyễn Văn Tân | M34: Regularly: 10 | N34: Positive: 15 | O34: Always: 20 | P34: Good: 10 | Q34: Often: 5 | R34: Regulary: 10 | S34: Good: 15 | T34: Tống Trường Thịn | U34: Regularly: 10 | V34: Positive: 15 | W34: Always: 20 | X34: Good: 10 | Y34: Regularly: 10 | Z34: Always: 15 | AA34: Medium: 10 | AB34: 20521920@gm.uit.edu.vn
A35: 44917.603 | B35: Quách Vinh Quang | C35: CS4273.N11.1 | D35: Sỹ | E35: Full: 15 | F35: Positive: 15 | G35: Always: 20 | H35: Good: 10 | I35: Regularly: 10 | J35: Always: 15 | K35: Good: 15 | L35: Thuận | M35: Full: 15 | N35: Positive: 15 | O35: Always: 20 | P35: Good: 10 | Q35: Regularly: 10 | R35: Always: 15 | S35: Good: 15 | T35: Thịnh | U35: Full: 15 | V35: Positive: 15 | W35: Always: 20 | X35: Good: 10 | Y35: Regularly: 10 | Z35: Always: 15 | AA35: Good: 15 | AB35: 20521811@gm.uit.edu.vn
A36: 44917.615 | B36: Kiều Xuân Diệu Hương | C36: CS4273.N11.1 | D36: Lê Quang Hòa | E36: Full: 15 | F36: Positive: 15 | G36: Always: 20 | H36: Good: 10 | I36: Regularly: 10 | J36: Always: 15 | K36: Good: 15 | L36: Bùi Thu Hà | M36: Full: 15 | N36: Positive: 15 | O36: Always: 20 | P36: Good: 10 | Q36: Regularly: 10 | R36: Always: 15 | S36: Good: 15 | T36: Phạm Thị Thùy Dương | U36: Full: 15 | V36: Positive: 15 | W36: Always: 20 | X36: Good: 10 | Y36: Regularly: 10 | Z36: Always: 15 | AA36: Good: 15 | AB36: 20521381@gm.uit.edu.vn
A37: 44917.616 | B37: Phạm Thị Thùy Dương | C37: CS4273.N11.1 | D37: Lê Quang Hòa | E37: Full: 15 | F37: Positive: 15 | G37: Always: 20 | H37: Good: 10 | I37: Regularly: 10 | J37: Always: 15 | K37: Good: 15 | L37: Kiều Xuân Diệu Hương | M37: Full: 15 | N37: Positive: 15 | O37: Always: 20 | P37: Good: 10 | Q37: Regularly: 10 | R37: Always: 15 | S37: Good: 15 | T37: Bùi Thu Hà | U37: Full: 15 | V37: Positive: 15 | W37: Always: 20 | X37: Good: 10 | Y37: Regularly: 10 | Z37: Always: 15 | AA37: Good: 15 | AB37: 20521221@gm.uit.edu.vn
A38: 44917.618 | B38: Bùi Thu Hà | C38: CS4273.N11.1 | D38: Kiều Xuân Diệu Hương | E38: Full: 15 | F38: Positive: 15 | G38: Always: 20 | H38: Good: 10 | I38: Regularly: 10 | J38: Always: 15 | K38: Good: 15 | L38: Lê Quang Hoà | M38: Full: 15 | N38: Positive: 15 | O38: Always: 20 | P38: Good: 10 | Q38: Regularly: 10 | R38: Always: 15 | S38: Good: 15 | T38: Phạm Thị Thuỳ Dương | U38: Full: 15 | V38: Positive: 15 | W38: Always: 20 | X38: Good: 10 | Y38: Regularly: 10 | Z38: Always: 15 | AA38: Good: 15 | AB38: 20521266@gm.uit.edu.vn
A39: 44917.625 | B39: Vương Thị Yến Nhi | C39: CS4273.N11.1 | D39: Huỳnh Khả Tú | E39: Full: 15 | F39: Positive: 15 | G39: Always: 20 | H39: Good: 10 | I39: Regularly: 10 | J39: Always: 15 | K39: Good: 15 | L39: Võ Hưng Khang | M39: Full: 15 | N39: Positive: 15 | O39: Always: 20 | P39: Good: 10 | Q39: Regularly: 10 | R39: Always: 15 | S39: Good: 15 | T39: Nguyễn Thúc Hoàng Hùng | U39: Full: 15 | V39: Positive: 15 | W39: Always: 20 | X39: Good: 10 | Y39: Regularly: 10 | Z39: Always: 15 | AA39: Good: 15 | AB39: 20521721@gm.uit.edu.vn
A40: 44917.626 | B40: Nguyen Thuc Hoang Hung | C40: CS4273.N11.1 | D40: Võ Hưng Khang | E40: Full: 15 | F40: Positive: 15 | G40: Always: 20 | H40: Good: 10 | I40: Regularly: 10 | J40: Always: 15 | K40: Good: 15 | L40: Võ Thị Yến Nhi | M40: Full: 15 | N40: Positive: 15 | O40: Always: 20 | P40: Good: 10 | Q40: Regularly: 10 | R40: Always: 15 | S40: Good: 15 | T40: Huỳnh Khả Tú | U40: Full: 15 | V40: Positive: 15 | W40: Always: 20 | X40: Good: 10 | Y40: Regularly: 10 | Z40: Always: 15 | AA40: Good: 15 | AB40: 20521370@gm.uit.edu.vn
A41: 44917.626 | B41: Võ Hưng Khang | C41: CS4273.N11.1 | D41: Vương Thị Yến Nhi | E41: Full: 15 | F41: Positive: 15 | G41: Always: 20 | H41: Good: 10 | I41: Regularly: 10 | J41: Always: 15 | K41: Good: 15 | L41: Huỳnh Khả Tú | M41: Full: 15 | N41: Positive: 15 | O41: Always: 20 | P41: Good: 10 | Q41: Regularly: 10 | R41: Always: 15 | S41: Good: 15 | T41: Nguyễn Thúc Hoàng Hùng | U41: Full: 15 | V41: Positive: 15 | W41: Always: 20 | X41: Good: 10 | Y41: Regularly: 10 | Z41: Always: 15 | AA41: Good: 15 | AB41: 20521440@gm.uit.edu.vn
A42: 44917.632 | B42: Nguyễn Phan Hiếu Thuận | C42: CS4273.N11.1 | D42: Lê Văn Sỹ | E42: Full: 15 | F42: Positive: 15 | G42: Always: 20 | H42: Good: 10 | I42: Regularly: 10 | J42: Always: 15 | K42: Good: 15 | L42: Nguyễn Xuân Thịnh | M42: Full: 15 | N42: Positive: 15 | O42: Always: 20 | P42: Good: 10 | Q42: Regularly: 10 | R42: Always: 15 | S42: Good: 15 | T42: Quách Vinh Quang | U42: Full: 15 | V42: Positive: 15 | W42: Always: 20 | X42: Good: 10 | Y42: Regularly: 10 | Z42: Always: 15 | AA42: Good: 15 | AB42: 20521994@gm.uit.edu.vn
A43: 44917.641 | B43: Lê Văn Sỹ | C43: CS4273.N11.1 | D43: Nguyễn Phan Hiếu Thuận | E43: Full: 15 | F43: Positive: 15 | G43: Always: 20 | H43: Good: 10 | I43: Regularly: 10 | J43: Always: 15 | K43: Good: 15 | L43: Nguyễn Xuân Thịnh | M43: Full: 15 | N43: Positive: 15 | O43: Always: 20 | P43: Good: 10 | Q43: Regularly: 10 | R43: Always: 15 | S43: Good: 15 | T43: Quách Vinh Quang | U43: Regularly: 10 | V43: Regularly: 10 | W43: Regularly: 15 | X43: Normal: 5 | Y43: Often: 5 | Z43: Regulary: 10 | AA43: Good: 15 | AB43: 20521854@gm.uit.edu.vn
A44: 44917.643 | B44: Trần Thái Thông | C44: CS4273.N11.1 | D44: Trần Nhân Đức | E44: Full: 15 | F44: Positive: 15 | G44: Always: 20 | H44: Good: 10 | I44: Regularly: 10 | J44: Always: 15 | K44: Good: 15 | AB44: 20521984@gm.uit.edu.vn
...

Sheet Trang tính2
A2: =Sheet1!B10 -> Trần Đức Duy | B2: =Sheet1!D10 -> Đậu Đình Quang Anh | C2: =RIGHT(Sheet1!E10,2)+RIGHT(Sheet1!F10,2)+RIGHT(Sheet1!G10,2)+RIGHT(Sheet1!H10,2)+RIGHT(Sheet1!I10,2)+RIGHT(Sheet1!J10,2)++RIGHT(Sheet1!K10,2) -> 100 | D2: =Sheet1!L10 -> Hà Gia Huy | E2: =RIGHT(Sheet1!M10,2)+RIGHT(Sheet1!N10,2)+RIGHT(Sheet1!O10,2)+RIGHT(Sheet1!P10,2)+RIGHT(Sheet1!Q10,2)+RIGHT(Sheet1!R10,2)++RIGHT(Sheet1!S10,2) -> 100 | F2: =Sheet1!T10 -> Nguyễn Đình Đan Thy | G2: =RIGHT(Sheet1!U10,2)+RIGHT(Sheet1!V10,2)+RIGHT(Sheet1!W10,2)+RIGHT(Sheet1!X10,2)+RIGHT(Sheet1!Y10,2)+RIGHT(Sheet1!Z10,2)++RIGHT(Sheet1!AA10,2) -> 100
A3: =Sheet1!B11 -> Huan Vo Trong | B3: =Sheet1!D11 -> Bùi Quang Giàu | C3: =RIGHT(Sheet1!E11,2)+RIGHT(Sheet1!F11,2)+RIGHT(Sheet1!G11,2)+RIGHT(Sheet1!H11,2)+RIGHT(Sheet1!I11,2)+RIGHT(Sheet1!J11,2)++RIGHT(Sheet1!K11,2) -> 90 | D3: =Sheet1!L11 -> Nguyễn Bảo Lâm | E3: =RIGHT(Sheet1!M11,2)+RIGHT(Sheet1!N11,2)+RIGHT(Sheet1!O11,2)+RIGHT(Sheet1!P11,2)+RIGHT(Sheet1!Q11,2)+RIGHT(Sheet1!R11,2)++RIGHT(Sheet1!S11,2) -> 90 | F3: =Sheet1!T11 -> Đỗ Công Trình | G3: =RIGHT(Sheet1!U11,2)+RIGHT(Sheet1!V11,2)+RIGHT(Sheet1!W11,2)+RIGHT(Sheet1!X11,2)+RIGHT(Sheet1!Y11,2)+RIGHT(Sheet1!Z11,2)++RIGHT(Sheet1!AA11,2) -> 100
A4: =Sheet1!B12 -> Nguyễn Đình Đan Thy | B4: =Sheet1!D12 -> Đậu Đình Quang Anh | C4: =RIGHT(Sheet1!E12,2)+RIGHT(Sheet1!F12,2)+RIGHT(Sheet1!G12,2)+RIGHT(Sheet1!H12,2)+RIGHT(Sheet1!I12,2)+RIGHT(Sheet1!J12,2)++RIGHT(Sheet1!K12,2) -> 100 | D4: =Sheet1!L12 -> Trần Đức Duy | E4: =RIGHT(Sheet1!M12,2)+RIGHT(Sheet1!N12,2)+RIGHT(Sheet1!O12,2)+RIGHT(Sheet1!P12,2)+RIGHT(Sheet1!Q12,2)+RIGHT(Sheet1!R12,2)++RIGHT(Sheet1!S12,2) -> 100 | F4: =Sheet1!T12 -> Hà Gia Huy | G4: =RIGHT(Sheet1!U12,2)+RIGHT(Sheet1!V12,2)+RIGHT(Sheet1!W12,2)+RIGHT(Sheet1!X12,2)+RIGHT(Sheet1!Y12,2)+RIGHT(Sheet1!Z12,2)++RIGHT(Sheet1!AA12,2) -> 100
A5: =Sheet1!B13 -> Hà Gia Huy | B5: =Sheet1!D13 -> Đậu Đình Quang Anh | C5: =RIGHT(Sheet1!E13,2)+RIGHT(Sheet1!F13,2)+RIGHT(Sheet1!G13,2)+RIGHT(Sheet1!H13,2)+RIGHT(Sheet1!I13,2)+RIGHT(Sheet1!J13,2)++RIGHT(Sheet1!K13,2) -> 100 | D5: =Sheet1!L13 -> Trần Đức Duy | E5: =RIGHT(Sheet1!M13,2)+RIGHT(Sheet1!N13,2)+RIGHT(Sheet1!O13,2)+RIGHT(Sheet1!P13,2)+RIGHT(Sheet1!Q13,2)+RIGHT(Sheet1!R13,2)++RIGHT(Sheet1!S13,2) -> 100 | F5: =Sheet1!T13 -> Nguyễn Đình Đan Thy | G5: =RIGHT(Sheet1!U13,2)+RIGHT(Sheet1!V13,2)+RIGHT(Sheet1!W13,2)+RIGHT(Sheet1!X13,2)+RIGHT(Sheet1!Y13,2)+RIGHT(Sheet1!Z13,2)++RIGHT(Sheet1!AA13,2) -> 100
A6: =Sheet1!B14 -> Đỗ Công Trình | B6: =Sheet1!D14 -> Võ Trọng Huân | C6: =RIGHT(Sheet1!E14,2)+RIGHT(Sheet1!F14,2)+RIGHT(Sheet1!G14,2)+RIGHT(Sheet1!H14,2)+RIGHT(Sheet1!I14,2)+RIGHT(Sheet1!J14,2)++RIGHT(Sheet1!K14,2) -> 100 | D6: =Sheet1!L14 -> Bùi Quang Giàu | E6: =RIGHT(Sheet1!M14,2)+RIGHT(Sheet1!N14,2)+RIGHT(Sheet1!O14,2)+RIGHT(Sheet1!P14,2)+RIGHT(Sheet1!Q14,2)+RIGHT(Sheet1!R14,2)++RIGHT(Sheet1!S14,2) -> 95 | F6: =Sheet1!T14 -> Nguyễn Bảo Lâm | G6: =RIGHT(Sheet1!U14,2)+RIGHT(Sheet1!V14,2)+RIGHT(Sheet1!W14,2)+RIGHT(Sheet1!X14,2)+RIGHT(Sheet1!Y14,2)+RIGHT(Sheet1!Z14,2)++RIGHT(Sheet1!AA14,2) -> 95
A7: =Sheet1!B15 -> Nguyễn Bảo Lâm | B7: =Sheet1!D15 -> Đỗ Công Trình | C7: =RIGHT(Sheet1!E15,2)+RIGHT(Sheet1!F15,2)+RIGHT(Sheet1!G15,2)+RIGHT(Sheet1!H15,2)+RIGHT(Sheet1!I15,2)+RIGHT(Sheet1!J15,2)++RIGHT(Sheet1!K15,2) -> 100 | D7: =Sheet1!L15 -> Bùi Quang Giàu | E7: =RIGHT(Sheet1!M15,2)+RIGHT(Sheet1!N15,2)+RIGHT(Sheet1!O15,2)+RIGHT(Sheet1!P15,2)+RIGHT(Sheet1!Q15,2)+RIGHT(Sheet1!R15,2)++RIGHT(Sheet1!S15,2) -> 100 | F7: =Sheet1!T15 -> Võ Trọng Huân | G7: =RIGHT(Sheet1!U15,2)+RIGHT(Sheet1!V15,2)+RIGHT(Sheet1!W15,2)+RIGHT(Sheet1!X15,2)+RIGHT(Sheet1!Y15,2)+RIGHT(Sheet1!Z15,2)++RIGHT(Sheet1!AA15,2) -> 85
A8: =Sheet1!B16 -> Lê Minh Thông | B8: =Sheet1!D16 -> Phạm Thị Dung | C8: =RIGHT(Sheet1!E16,2)+RIGHT(Sheet1!F16,2)+RIGHT(Sheet1!G16,2)+RIGHT(Sheet1!H16,2)+RIGHT(Sheet1!I16,2)+RIGHT(Sheet1!J16,2)++RIGHT(Sheet1!K16,2) -> 100 | D8: =Sheet1!L16 -> Trần Trọng Sang | E8: =RIGHT(Sheet1!M16,2)+RIGHT(Sheet1!N16,2)+RIGHT(Sheet1!O16,2)+RIGHT(Sheet1!P16,2)+RIGHT(Sheet1!Q16,2)+RIGHT(Sheet1!R16,2)++RIGHT(Sheet1!S16,2) -> 85 | F8: =Sheet1!T16 -> Võ Anh Hào | G8: =RIGHT(Sheet1!U16,2)+RIGHT(Sheet1!V16,2)+RIGHT(Sheet1!W16,2)+RIGHT(Sheet1!X16,2)+RIGHT(Sheet1!Y16,2)+RIGHT(Sheet1!Z16,2)++RIGHT(Sheet1!AA16,2) -> 60
A9: =Sheet1!B17 -> Trần Trọng Sang | B9: =Sheet1!D17 -> Trần Trọng Sang | C9: =RIGHT(Sheet1!E17,2)+RIGHT(Sheet1!F17,2)+RIGHT(Sheet1!G17,2)+RIGHT(Sheet1!H17,2)+RIGHT(Sheet1!I17,2)+RIGHT(Sheet1!J17,2)++RIGHT(Sheet1!K17,2) -> 75 | D9: =Sheet1!L17 -> Phạm Thùy Dung | E9: =RIGHT(Sheet1!M17,2)+RIGHT(Sheet1!N17,2)+RIGHT(Sheet1!O17,2)+RIGHT(Sheet1!P17,2)+RIGHT(Sheet1!Q17,2)+RIGHT(Sheet1!R17,2)++RIGHT(Sheet1!S17,2) -> 90 | F9: =Sheet1!T17 -> Lê Minh Thông | G9: =RIGHT(Sheet1!U17,2)+RIGHT(Sheet1!V17,2)+RIGHT(Sheet1!W17,2)+RIGHT(Sheet1!X17,2)+RIGHT(Sheet1!Y17,2)+RIGHT(Sheet1!Z17,2)++RIGHT(Sheet1!AA17,2) -> 100
A10: =Sheet1!B18 -> Đồng Phúc Nhẫn | B10: =Sheet1!D18 -> Nghĩa | C10: =RIGHT(Sheet1!E18,2)+RIGHT(Sheet1!F18,2)+RIGHT(Sheet1!G18,2)+RIGHT(Sheet1!H18,2)+RIGHT(Sheet1!I18,2)+RIGHT(Sheet1!J18,2)++RIGHT(Sheet1!K18,2) -> 100 | D10: =Sheet1!L18 -> Bình | E10: =RIGHT(Sheet1!M18,2)+RIGHT(Sheet1!N18,2)+RIGHT(Sheet1!O18,2)+RIGHT(Sheet1!P18,2)+RIGHT(Sheet1!Q18,2)+RIGHT(Sheet1!R18,2)++RIGHT(Sheet1!S18,2) -> 100 | F10: =Sheet1!T18 -> Tỷ | G10: =RIGHT(Sheet1!U18,2)+RIGHT(Sheet1!V18,2)+RIGHT(Sheet1!W18,2)+RIGHT(Sheet1!X18,2)+RIGHT(Sheet1!Y18,2)+RIGHT(Sheet1!Z18,2)++RIGHT(Sheet1!AA18,2) -> 100
A11: =Sheet1!B19 -> Phạm Phước Tỷ | B11: =Sheet1!D19 -> Nghĩa | C11: =RIGHT(Sheet1!E19,2)+RIGHT(Sheet1!F19,2)+RIGHT(Sheet1!G19,2)+RIGHT(Sheet1!H19,2)+RIGHT(Sheet1!I19,2)+RIGHT(Sheet1!J19,2)++RIGHT(Sheet1!K19,2) -> 100 | D11: =Sheet1!L19 -> Nhẫn | E11: =RIGHT(Sheet1!M19,2)+RIGHT(Sheet1!N19,2)+RIGHT(Sheet1!O19,2)+RIGHT(Sheet1!P19,2)+RIGHT(Sheet1!Q19,2)+RIGHT(Sheet1!R19,2)++RIGHT(Sheet1!S19,2) -> 100 | F11: =Sheet1!T19 -> Bình | G11: =RIGHT(Sheet1!U19,2)+RIGHT(Sheet1!V19,2)+RIGHT(Sheet1!W19,2)+RIGHT(Sheet1!X19,2)+RIGHT(Sheet1!Y19,2)+RIGHT(Sheet1!Z19,2)++RIGHT(Sheet1!AA19,2) -> 100
A12: =Sheet1!B20 -> Ngô Bá Trọng Nghĩa | B12: =Sheet1!D20 -> Đồng Phúc Nhẫn | C12: =RIGHT(Sheet1!E20,2)+RIGHT(Sheet1!F20,2)+RIGHT(Sheet1!G20,2)+RIGHT(Sheet1!H20,2)+RIGHT(Sheet1!I20,2)+RIGHT(Sheet1!J20,2)++RIGHT(Sheet1!K20,2) -> 100 | D12: =Sheet1!L20 -> Nguyễn Thanh Bình | E12: =RIGHT(Sheet1!M20,2)+RIGHT(Sheet1!N20,2)+RIGHT(Sheet1!O20,2)+RIGHT(Sheet1!P20,2)+RIGHT(Sheet1!Q20,2)+RIGHT(Sheet1!R20,2)++RIGHT(Sheet1!S20,2) -> 100 | F12: =Sheet1!T20 -> Phạm Phước Tỷ | G12: =RIGHT(Sheet1!U20,2)+RIGHT(Sheet1!V20,2)+RIGHT(Sheet1!W20,2)+RIGHT(Sheet1!X20,2)+RIGHT(Sheet1!Y20,2)+RIGHT(Sheet1!Z20,2)++RIGHT(Sheet1!AA20,2) -> 100
A13: =Sheet1!B21 -> Lê Trí Khoa | B13: =Sheet1!D21 -> Lâm Lê Phúc Huy | C13: =RIGHT(Sheet1!E21,2)+RIGHT(Sheet1!F21,2)+RIGHT(Sheet1!G21,2)+RIGHT(Sheet1!H21,2)+RIGHT(Sheet1!I21,2)+RIGHT(Sheet1!J21,2)++RIGHT(Sheet1!K21,2) -> 90 | D13: =Sheet1!L21 -> Nguyễn Hữu Thiên | E13: =RIGHT(Sheet1!M21,2)+RIGHT(Sheet1!N21,2)+RIGHT(Sheet1!O21,2)+RIGHT(Sheet1!P21,2)+RIGHT(Sheet1!Q21,2)+RIGHT(Sheet1!R21,2)++RIGHT(Sheet1!S21,2) -> 80 | F13: =Sheet1!T21 -> Nguyễn Phi Hùng | G13: =RIGHT(Sheet1!U21,2)+RIGHT(Sheet1!V21,2)+RIGHT(Sheet1!W21,2)+RIGHT(Sheet1!X21,2)+RIGHT(Sheet1!Y21,2)+RIGHT(Sheet1!Z21,2)++RIGHT(Sheet1!AA21,2) -> 80
... A47: =Sheet1!B55 -> Hồ Văn Hiệu | B47: =Sheet1!D55 -> Dương Minh Thành | C47: =RIGHT(Sheet1!E55,2)+RIGHT(Sheet1!F55,2)+RIGHT(Sheet1!G55,2)+RIGHT(Sheet1!H55,2)+RIGHT(Sheet1!I55,2)+RIGHT(Sheet1!J55,2)++RIGHT(Sheet1!K55,2) -> 85 | D47: =Sheet1!L55 -> Nguyễn Thị Minh Loan | E47: =RIGHT(Sheet1!M55,2)+RIGHT(Sheet1!N55,2)+RIGHT(Sheet1!O55,2)+RIGHT(Sheet1!P55,2)+RIGHT(Sheet1!Q55,2)+RIGHT(Sheet1!R55,2)++RIGHT(Sheet1!S55,2) -> 95 | F47: =Sheet1!T55 | G47: =RIGHT(Sheet1!U55,2)+RIGHT(Sheet1!V55,2)+RIGHT(Sheet1!W55,2)+RIGHT(Sheet1!X55,2)+RIGHT(Sheet1!Y55,2)+RIGHT(Sheet1!Z55,2)++RIGHT(Sheet1!AA55,2) -> 0
A48: =Sheet1!B60 | B48: =Sheet1!D60 | C48: =RIGHT(Sheet1!E60,2)+RIGHT(Sheet1!F60,2)+RIGHT(Sheet1!G60,2)+RIGHT(Sheet1!H60,2)+RIGHT(Sheet1!I60,2)+RIGHT(Sheet1!J60,2)++RIGHT(Sheet1!K60,2) -> 0 | D48: =Sheet1!L60 | E48: =RIGHT(Sheet1!M60,2)+RIGHT(Sheet1!N60,2)+RIGHT(Sheet1!O60,2)+RIGHT(Sheet1!P60,2)+RIGHT(Sheet1!Q60,2)+RIGHT(Sheet1!R60,2)++RIGHT(Sheet1!S60,2) -> 0 | F48: =Sheet1!T60 | G48: =RIGHT(Sheet1!U60,2)+RIGHT(Sheet1!V60,2)+RIGHT(Sheet1!W60,2)+RIGHT(Sheet1!X60,2)+RIGHT(Sheet1!Y60,2)+RIGHT(Sheet1!Z60,2)++RIGHT(Sheet1!AA60,2) -> 0
A49: =Sheet1!B61 | B49: =Sheet1!D61 | C49: =RIGHT(Sheet1!E61,2)+RIGHT(Sheet1!F61,2)+RIGHT(Sheet1!G61,2)+RIGHT(Sheet1!H61,2)+RIGHT(Sheet1!I61,2)+RIGHT(Sheet1!J61,2)++RIGHT(Sheet1!K61,2) -> 0 | D49: =Sheet1!L61 | E49: =RIGHT(Sheet1!M61,2)+RIGHT(Sheet1!N61,2)+RIGHT(Sheet1!O61,2)+RIGHT(Sheet1!P61,2)+RIGHT(Sheet1!Q61,2)+RIGHT(Sheet1!R61,2)++RIGHT(Sheet1!S61,2) -> 0 | F49: =Sheet1!T61 | G49: =RIGHT(Sheet1!U61,2)+RIGHT(Sheet1!V61,2)+RIGHT(Sheet1!W61,2)+RIGHT(Sheet1!X61,2)+RIGHT(Sheet1!Y61,2)+RIGHT(Sheet1!Z61,2)++RIGHT(Sheet1!AA61,2) -> 0
